11:49:06,639 __main__ ERROR name 'data_folder' is not defined
Traceback (most recent call last):
  File "/opt/src/geti/installer/app/platform_installer.py", line 35, in <module>
    cli()
  File "/opt/src/geti/src/installer/platform_installer/.venv-platform-installer/lib/python3.12/site-packages/click/core.py", line 1157, in __call__
    return self.main(*args, **kwargs)
           ^^^^^^^^^^^^^^^^^^^^^^^^^^
  File "/opt/src/geti/src/installer/platform_installer/.venv-platform-installer/lib/python3.12/site-packages/rich_click/rich_group.py", line 21, in main
    return super().main(*args, standalone_mode=False, **kwargs)
           ^^^^^^^^^^^^^^^^^^^^^^^^^^^^^^^^^^^^^^^^^^^^^^^^^^^^
  File "/opt/src/geti/src/installer/platform_installer/.venv-platform-installer/lib/python3.12/site-packages/click/core.py", line 1078, in main
    rv = self.invoke(ctx)
         ^^^^^^^^^^^^^^^^
  File "/opt/src/geti/src/installer/platform_installer/.venv-platform-installer/lib/python3.12/site-packages/click/core.py", line 1688, in invoke
    return _process_result(sub_ctx.command.invoke(sub_ctx))
                           ^^^^^^^^^^^^^^^^^^^^^^^^^^^^^^^
  File "/opt/src/geti/src/installer/platform_installer/.venv-platform-installer/lib/python3.12/site-packages/click/core.py", line 1434, in invoke
    return ctx.invoke(self.callback, **ctx.params)
           ^^^^^^^^^^^^^^^^^^^^^^^^^^^^^^^^^^^^^^^
  File "/opt/src/geti/src/installer/platform_installer/.venv-platform-installer/lib/python3.12/site-packages/click/core.py", line 783, in invoke
    return __callback(*args, **kwargs)
           ^^^^^^^^^^^^^^^^^^^^^^^^^^^
  File "/opt/src/geti/installer/app/commands/install.py", line 132, in install
    config = InstallationConfig(interactive_mode=True)
             ^^^^^^^^^^^^^^^^^^^^^^^^^^^^^^^^^^^^^^^^^
  File "/opt/src/geti/installer/app/configuration_models/install_config.py", line 66, in __init__
    self.data_folder = ConfigurationField(type=str, required=False, value=data_folder)
                                                                          ^^^^^^^^^^^
NameError: name 'data_folder' is not defined
